<!-- ======================================================
	This file is part of MuJoCo.
	Copyright 2009-2015 Roboti LLC.

	Model 		:: PR2 from Willow Garage
		Source		: (Provided by Sergey Levine, UC Berkeley)
		Downloaded	: 18July'14

	Mujoco		:: Advanced physics simulation engine
		Source		: www.roboti.us
		Version		: 1.22
		Released 	: 26Nov15

	Author		:: Vikash Kumar
		Contacts 	: kumar@roboti.us
		Last edits 	: 14Dec'15, 10Oct'15
====================================================== -->
<mujoco model="pr2(v1.22)">
    <compiler 	meshdir="meshes/"
				coordinate="local"
				angle="radian"/>

	<option timestep="0.05" gravity="0 0 0" collision="all"/>
	<asset>
		<mesh file="base_L.stl"/>
		<mesh file="caster_L.stl"/>
		<mesh file="torso_lift_L.stl"/>
		<mesh file="head_pan_L.stl"/>
		<mesh file="head_tilt_L.stl"/>
		<mesh file="tilting_hokuyo_L.stl"/>
		<mesh file="shoulder_pan.stl"/>
		<mesh file="shoulder_lift.stl"/>
		<mesh file="upper_arm_roll_L.stl"/>
		<mesh file="upper_arm.stl"/>
		<mesh file="elbow_flex.stl"/>
		<mesh file="forearm_roll_L.stl"/>
		<mesh file="forearm.stl"/>


		<mesh file="wrist_flex.stl"/>
		<mesh file="wrist_roll_L.stl"/>
		<mesh file="gripper_palm.stl"/>
		<mesh file="l_finger.stl"/>
		<mesh file="l_finger_tip.stl"/>

		<material name="MatGnd" specular=".3" shininess=".3" reflectance="0.3" rgba=".5 .55 .5 1"/>
	</asset>



    <contact>
        <pair geom1="r_gripper_l_finger_tip" geom2="r_gripper_r_finger_tip"/>
		<pair geom1="l_gripper_l_finger_tip" geom2="l_gripper_r_finger_tip"/>
		<pair geom1="base" geom2="r_forearm"/>
		<pair geom1="base" geom2="l_forearm"/>
    </contact>

    <default>
        <joint limited="false" damping=".01" armature=".005" frictional="false"/>
        <geom contype="1" conaffinity="0" friction="1 0.1 0.1" type="mesh"/>
		<default class="gripper">
			<joint damping="0.005" armature=".005"/>
		</default>
    </default>

    <worldbody>
	<light directional="true" cutoff="4" exponent="20" diffuse="1 1 1" specular="0 0 0" pos=".5 0.75 1.5" dir="-.5 -0.75 -1.5"/>
	<geom name="gnd" material="MatGnd" type="plane" contype="0" conaffinity="1" pos="0 0 0" size="1.5 1.5 0.25"/>

        <body name="base_footprint" pos="0 0 0">
            <inertial pos="0 0 0" mass="1" diaginertia="0.01 0.01 0.01" />
            <!--<geom name="geom0" type="box" pos="0 0 0.071" size="0.005 0.005 0.005" rgba="1 0 0 1" group="2" />-->
            <body name="base_link" pos="0 0 0.051">
                <inertial pos="-0.061 0 0.293" quat="0.973598 0.001764 -0.228065 -0.009443" mass="116" diaginertia="6.293885 5.669245 3.041772" />
                <geom name="base" rgba="1 1 1 1" mesh="base_L" contype="0"/>

                <body name="torso_lift_link" pos="-0.05 0 0.739675">
                    <inertial pos="-0.1 0 -0.0885" quat="0.999335 0.007626 0.035453 0.003712" mass="36.248046" diaginertia="2.783075 2.510450 0.514581" />
                    <!--<joint name="torso_lift_joint" type="slide" pos="0 0 0" axis="0 0 1" limited="true" range="0 0.31"/>-->
                    <geom name="geom15" rgba="0.9 0.9 0.9 1" mesh="torso_lift_L" contype="0"/>

                    <body name="l_shoulder_pan_link" pos="0 0.188 0">
                        <inertial pos="-0.001201 0.024513 -0.098231" quat="0.927482 -0.087656 0.074060 -0.355821" mass="25.799322" diaginertia="0.934201 0.837701 0.242033" />
                        <joint name="l_shoulder_pan_joint" type="hinge" pos="0 0 0" axis="0 0 1" limited="true" range="-0.714602 2.285398" damping="10.0"/>
                        <geom name="geom50" rgba="0.7 0.7 0.7 1" mesh="shoulder_pan" contype="0"/>

                        <body name="l_shoulder_lift_link" pos="0.1 0 0">
                            <inertial pos="0.02195 -0.02664 -0.03127" quat="0.791779 0.478014 0.238985 0.295762" mass="2.74988" diaginertia="0.026187 0.020730 0.015168" />
                            <joint name="l_shoulder_lift_joint" type="hinge" pos="0 0 0" axis="0 1 0" limited="true" range="-0.5236 1.3963" damping="10.0"/>
                            <geom name="geom51" rgba="0.7 0.7 0.7 1" mesh="shoulder_lift" />
                            <body name="l_upper_arm_roll_link" pos="0 0 0">
                                <inertial pos="0 0 0" mass="0.1" diaginertia="0.01 0.01 0.01"/>
                                <joint name="l_upper_arm_roll_joint" type="hinge" pos="0 0 0" axis="1 0 0" limited="true" range="-0.8 3.9" damping="0.1"/>
                                <body name="l_upper_arm_link" pos="0 0 0">
                                    <inertial pos="0.21405 0.01658 -0.00057" quat="-0.090901 0.708675 -0.051638 0.697746" mass="6.01769" diaginertia="0.076070 0.074882 0.015107" />
                                    <geom name="geom53" rgba="0.7 0.7 0.7 1" mesh="upper_arm" contype="0"/>
                                    <body name="l_elbow_flex_link" pos="0.4 0 0">
                                        <inertial pos="0.01014 0.00032 -0.01211" quat="0.308784 0.646797 0.639077 0.279083" mass="1.90327" diaginertia="0.004419 0.003965 0.003090" />
                                        <joint name="l_elbow_flex_joint" type="hinge" pos="0 0 0" axis="0 1 0" limited="true" range="-2.3213 0" damping="1.0"/>
                                        <geom name="geom54" rgba="0.7 0.7 0.7 1" mesh="elbow_flex" />
                                        <body name="l_forearm_roll_link" pos="0 0 0">
                                            <inertial pos="0 0 0" mass="0.1" diaginertia="0.01 0.01 0.01"/>
                                            <joint name="l_forearm_roll_joint" type="hinge"   pos="0 0 0" axis="1 0 0" damping="1.0"/>
                                            <body name="l_forearm_link" pos="0 0 0">
                                                <inertial pos="0.18791 -0.00017 -0.00912" quat="-0.000587 0.726286 -0.003969 0.687381" mass="2.57968" diaginertia="0.016633 0.015078 0.003609" />
                                                <geom name="l_forearm" rgba="0.7 0.7 0.7 1" mesh="forearm" contype="0"/>
                                                <body name="l_wrist_flex_link" pos="0.321 0 0">
                                                    <inertial pos="-0.00157 0 -0.00075" quat="0.695976 0.696411 -0.123560 0.123942" mass="0.61402" diaginertia="0.000653 0.000643 0.000198" />
                                                    <joint name="l_wrist_flex_joint" type="hinge" pos="0 0 0" axis="0 1 0" limited="true" range="-2.094 0" damping="0.1"/>
                                                    <geom name="geom57" rgba="0.7 0.7 0.7 1" mesh="wrist_flex" contype="0"/>
                                                    <body name="l_wrist_roll_link" pos="0 0 0">
                                                        <inertial pos="0 0 0" mass="0.1" diaginertia="0.01 0.01 0.01" />
                                                        <joint name="l_wrist_roll_joint" type="hinge"   pos="0 0 0" axis="1 0 0" damping="0.1"/>
                                                        <!--mesh name="geom58" mesh="wrist_roll_L" /-->
                                                        <body name="l_gripper_palm_link" pos="0.038 0 0" childclass="gripper">
                                                            <inertial pos="0.06623 0.00053 -0.00119" quat="-0.018184 0.706274 0.016077 0.707523" mass="0.58007" diaginertia="0.000866 0.000678 0.000351" />
                                                            <geom name="geom59" rgba="0.7 0.7 0.7 1" mesh="gripper_palm" pos="0 0 0"/>
                                                            <body name="sensor" pos="0.01 0 0">
                                                                <geom name="sensor" rgba="0.7 0.7 0.7 1" type="cylinder" size="0.022 0.019" pos="0 0 0" quat="-0.018184 0.706274 0.016077 0.707523"/>
                                                            </body>
                                                            <!--geom name="geom59f" type="capsule" pos="0.07750326 -0.00000579 -0.00000142" quat="0.49981788 0.50015276 -0.49991269 0.50011660" size="0.05263874 0.00669171" rgba="0.8 0 0 1" group="1" contype="1"/-->
                                                            <body name="l_gripper_led_frame" pos="0.0513 0 0.0244">
                                                                <inertial pos="0 0 0" mass="0.001" diaginertia="0.000000 0.000000 0.000000" />
                                                            </body>
                                                            <body name="l_gripper_motor_accelerometer_link" pos="0 0 0">
                                                                <inertial pos="0 0 0" mass="0.001" diaginertia="0.001 0.001 0.001" />
                                                                <geom name="geom60" type="box" pos="0 0 0" size="0.0005 0.0005 0.0005" />
                                                            </body>

                                                                <body name="l_gripper_l_finger_link" pos="0.07691 0.01 0">
                                                                <inertial pos="0.03598 0.0173 -0.00164" quat="0.574440 0.429111 0.518782 0.465562" mass="0.17126" diaginertia="0.000198 0.000181 0.000077" />
                                                                <!--<joint name="l_gripper_l_finger_joint" type="hinge" pos="0 0 0" axis="0 0 1" limited="true" range="0 0.548"/>-->
                                                                <geom name="geom61" rgba="0.7 0.7 0.7 1" mesh="l_finger" />
                                                                <body name="l_gripper_l_finger_tip_link" pos="0.09137 0.00495 0">
                                                                    <inertial pos="0.00423 0.00284 0" quat="0.249588 0.661594 -0.249588 0.661594" mass="0.04419" diaginertia="0.000015 0.000015 0.000003" />
                                                                    <!--<joint name="l_gripper_l_finger_tip_joint" type="hinge" pos="0 0 0" axis="0 0 1" limited="true" range="-.548 0"/>-->
                                                                    <geom name="l_gripper_l_finger_tip" rgba="0.7 0.7 0.7 1" mesh="l_finger_tip" />
                                                                </body>

                                                            </body>
                                                            <body name="l_gripper_r_finger_link" pos="0.07691 -0.01 0">
                                                                <inertial pos="0.03576 -0.01736 -0.00095" quat="0.474684 0.510909 0.446353 0.560727" mass="0.17389" diaginertia="0.000199 0.000181 0.000077" />
                                                                <geom name="geom63" euler="3.14 0 0" rgba="0.7 0.7 0.7 1" mesh="l_finger" />
                                                                    <site name="tip" pos="0 0 0" size="0.01"/>

                                                                <body name="l_gripper_r_finger_tip_link" pos="0.09137 -0.00495 0">
                                                                    <inertial pos="0.00423 -0.00284 0" quat="-0.249588 0.661594 0.249588 0.661594" mass="0.04419" diaginertia="0.000015 0.000015 0.000003" />
                                                                    <geom name="l_gripper_r_finger_tip" euler="3.14 0 0" rgba="0.7 0.7 0.7 1" mesh="l_finger_tip" />

                                                                </body>

                                                        </body>


                                                        </body>
                                                    </body>
                                                </body>
                                            </body>

                                        </body>
                                    </body>
                                </body>
                            </body>
                        </body>
                    </body>

                    <body name="r_shoulder_pan_link" pos="0 -0.188 0">
                        <inertial pos="-0.001201 0.024513 -0.098231" quat="0.927482 -0.087656 0.074060 -0.355821" mass="25.799322" diaginertia="0.934201 0.837701 0.242033" />

                        <!--<joint name="r_shoulder_pan_joint" type="hinge" pos="0 0 0" axis="0 0 1" limited="true" range="-0.719 -0.718" />-->
                        <geom name="geom32" rgba="0.7 0.7 0.7 1" mesh="shoulder_pan" contype="0"/>

                        <body name="r_shoulder_lift_link" pos="0.1 0 0">
                            <inertial pos="0.02195 -0.02664 -0.03127" quat="0.791779 0.478014 0.238985 0.295762" mass="2.74988" diaginertia="0.026187 0.020730 0.015168" />

                            <!--<joint name="r_shoulder_lift_joint" type="hinge" pos="0 0 0" axis="0 1 0" limited="true" range="-0.23 -0.2"/>-->
                            <geom name="geom33" rgba="0.7 0.7 0.7 1" mesh="shoulder_lift" contype="0"/>
                            <body name="r_upper_arm_roll_link" pos="0 0 0">
                                <inertial pos="0 0 0" mass="0.1" diaginertia="0.01 0.01 0.01" />

                                <!--<joint name="r_upper_arm_roll_joint" type="hinge" pos="0 0 0" axis="1 0 0" limited="true" range="-1.2 -1.1"/>-->
                                <body name="r_upper_arm_link" pos="0 0 0">
                                    <inertial pos="0.21398 -0.01621 -0.0002" quat="-0.045020 0.697462 -0.088537 0.709705" mass="6.01769" diaginertia="0.076138 0.074931 0.015133" />
                                    <geom name="geom35" rgba="0.7 0.7 0.7 1" mesh="upper_arm" contype="0"/>
                                    <body name="r_elbow_flex_link" pos="0.4 0 0">
                                        <inertial pos="0.01014 0.00032 -0.01211" quat="0.308784 0.646797 0.639077 0.279083" mass="1.90327" diaginertia="0.004419 0.003965 0.003090" />

                                        <!--<joint name="r_elbow_flex_joint" type="hinge" pos="0 0 0" axis="0 1 0" limited="true" range="-1.052 -1.051"/>-->
                                        <geom name="geom36" rgba="0.7 0.7 0.7 1" mesh="elbow_flex" contype="0"/>
                                        <body name="r_forearm_roll_link" pos="0 0 0">
                                            <inertial pos="0 0 0" mass="0.1" diaginertia="0.01 0.01 0.01" />

                                            <!--<joint name="r_forearm_roll_joint" type="hinge"   pos="0 0 0" axis="1 0 0" limited="true" range="36.11 36.12"/>-->
                                            <body name="r_forearm_link" pos="0 0 0">
                                                <inertial pos="0.18791 -0.00017 -0.00912" quat="-0.000587 0.726286 -0.003969 0.687381" mass="2.57968" diaginertia="0.016633 0.015078 0.003609" />
                                                <geom name="r_forearm" rgba="0.7 0.7 0.7 1" mesh="forearm" contype="0"/>

                                                <body name="r_wrist_flex_link" pos="0.321 0 0">
                                                    <inertial pos="-0.00157 0 -0.00075" quat="0.695976 0.696411 -0.123560 0.123942" mass="0.61402" diaginertia="0.000653 0.000643 0.000198" />

                                                    <!--<joint name="r_wrist_flex_joint" type="hinge" pos="0 0 0" axis="0 1 0" limited="true" range="-1.9 -1.8"/>-->
                                                    <geom name="geom39" rgba="0.7 0.7 0.7 1" mesh="wrist_flex" contype="0"/>
                                                    <body name="r_wrist_roll_link" pos="0 0 0">
                                                        <inertial pos="0 0 0" mass="0.1" diaginertia="0.01 0.01 0.01" />

                                                        <!--<joint name="r_wrist_roll_joint" type="hinge"   pos="0 0 0" axis="1 0 0" limited="true" range="-78.7 -78.66"/>-->
                                                        <body name="r_gripper_palm_link" pos="0 0 0" childclass="gripper">
                                                            <inertial pos="0.06623 0.00053 -0.00119" quat="-0.018184 0.706274 0.016077 0.707523" mass="0.58007" diaginertia="0.000866 0.000678 0.000351" />
                                                            <geom name="geom41" rgba="0.7 0.7 0.7 1" mesh="gripper_palm" contype="0"/>

                                                            <body name="r_gripper_tool_frame" pos="0.18 0 0">
                                                                <inertial pos="0 0 0" mass="0.001" diaginertia="0.000000 0.000000 0.000000" />

                                                            </body>
                                                            <body name="r_gripper_l_finger_link" pos="0.07691 0.01 0">
                                                                <inertial pos="0.03598 0.0173 -0.00164" quat="0.574440 0.429111 0.518782 0.465562" mass="0.17126" diaginertia="0.000198 0.000181 0.000077" />
                                                                <geom name="geom43" rgba="0.7 0.7 0.7 1" mesh="l_finger" />
                                                                <body name="r_gripper_l_finger_tip_link" pos="0.09137 0.00495 0">
                                                                    <inertial pos="0.00423 0.00284 0" quat="0.249588 0.661594 -0.249588 0.661594" mass="0.04419" diaginertia="0.000015 0.000015 0.000003" />
                                                                    <geom name="r_gripper_l_finger_tip" rgba="0.7 0.7 0.7 1" mesh="l_finger_tip" />
                                                                </body>
                                                            </body>
                                                            <body name="r_gripper_r_finger_link" pos="0.07691 -0.01 0">
                                                                <inertial pos="0.03576 -0.01736 -0.00095" quat="0.474684 0.510909 0.446353 0.560727" mass="0.17389" diaginertia="0.000199 0.000181 0.000077" />
                                                                <geom name="geom45" rgba="0.7 0.7 0.7 1" euler="3.14 0 0" mesh="l_finger" />
                                                                <body name="r_gripper_r_finger_tip_link" pos="0.09137 -0.00495 0">
                                                                    <inertial pos="0.00423 -0.00284 0" quat="-0.249588 0.661594 0.249588 0.661594" mass="0.04419" diaginertia="0.000015 0.000015 0.000003" />
                                                                    <geom name="r_gripper_r_finger_tip" euler="3.14 0 0" rgba="0.7 0.7 0.7 1" mesh="l_finger_tip" />
                                                                </body>
                                                            </body>

                                                        </body>
                                                    </body>
                                                </body>
                                            </body>

                                        </body>
                                    </body>
                                </body>
                            </body>
                        </body>
                    </body>
                </body>

            </body>
        </body>


        <body name="target" pos="0 0 0">
            <joint armature="0" axis="1 0 0" damping="0" name="target_x" pos="0 0 0" ref="0" stiffness="0" type="slide"/>
            <joint armature="0" axis="0 1 0" damping="0" name="target_y" pos="0 0 0" ref="0" stiffness="0" type="slide"/>
            <joint armature="0" axis="0 0 1" damping="0" name="target_z" pos="0 0 0" ref="0" stiffness="0" type="slide"/>
            <geom conaffinity="0" contype="0" name="target" pos="0 0 0" rgba="0.9 0.6 0.2 1" size=".02" type="sphere"/>
        </body>

    </worldbody>
<actuator>
    <motor joint="l_shoulder_pan_joint" ctrlrange="-3.0 3.0" ctrllimited="true"/>
    <motor joint="l_shoulder_lift_joint" ctrlrange="-3.0 3.0" ctrllimited="true"/>
    <motor joint="l_upper_arm_roll_joint" ctrlrange="-3.0 3.0" ctrllimited="true"/>
    <motor joint="l_elbow_flex_joint" ctrlrange="-3.0 3.0" ctrllimited="true"/>
    <motor joint="l_forearm_roll_joint" ctrlrange="-3.0 3.0" ctrllimited="true"/>
    <motor joint="l_wrist_flex_joint" ctrlrange="-3.0 3.0" ctrllimited="true"/>
    <motor joint="l_wrist_roll_joint" ctrlrange="-3.0 3.0" ctrllimited="true"/>
    <!--general site="lego_target" gear="0 0 -1 0 0 0" dynprm="0 0 0" gainprm="0 0 0" biastype="affine" biasprm="0.981 0 0"/-->
</actuator>


</mujoco>
